Workbook

Sheet data
A1: loan_id | B1: loan_purpose | C1: loan_amount | D1: interest_rate | E1: dti_ratio | F1: defaulted | G1: employment_status | H1: years_employed | I1: annual_income | J1: credit_score | K1: credit_score bucket | L1: Dti_ratio2 | M1: tenure_group
A2: LN-00001 | B2: Vacation | C2: 16100 | D2: 13.05 | E2: 55.5 | F2: 0 | G2: Self-Employed | H2: 6 | I2: 31020 | J2: 596 | K2: {=_xlfn.IFS(J2<600,"520-599",J2<650,"600-649",J2<700,"650-699",J2<750,"700-749",TRUE,"750+")} -> 520-599 | L2: {=_xlfn.IFS(E2<20,"1. Under 20",E2<30,"2. 20-29",E2<40,"3. 30-39",E2<50,"4. 40-49",E2<60,"5. 50-59",E2<70,"6. 60-69",E2<80,"7. 70-79",TRUE,"8. 80+")} -> 5. 50-59 | M2: =IF(H2<2,"Under 2 years","2+ years") -> 2+ years
A3: LN-00002 | B3: Major Purchase | C3: 5600 | D3: 14.21 | E3: 40.4 | F3: 1 | G3: Self-Employed | H3: 6 | I3: 31020 | J3: 596 | K3: {=_xlfn.IFS(J3<600,"520-599",J3<650,"600-649",J3<700,"650-699",J3<750,"700-749",TRUE,"750+")} -> 520-599 | L3: {=_xlfn.IFS(E3<20,"1. Under 20",E3<30,"2. 20-29",E3<40,"3. 30-39",E3<50,"4. 40-49",E3<60,"5. 50-59",E3<70,"6. 60-69",E3<80,"7. 70-79",TRUE,"8. 80+")} -> 4. 40-49 | M3: =IF(H3<2,"Under 2 years","2+ years") -> 2+ years
A4: LN-00003 | B4: Moving | C4: 44700 | D4: 12.37 | E4: 70.5 | F4: 0 | G4: Full-Time | H4: 4 | I4: 40188 | J4: 543 | K4: {=_xlfn.IFS(J4<600,"520-599",J4<650,"600-649",J4<700,"650-699",J4<750,"700-749",TRUE,"750+")} -> 520-599 | L4: {=_xlfn.IFS(E4<20,"1. Under 20",E4<30,"2. 20-29",E4<40,"3. 30-39",E4<50,"4. 40-49",E4<60,"5. 50-59",E4<70,"6. 60-69",E4<80,"7. 70-79",TRUE,"8. 80+")} -> 7. 70-79 | M4: =IF(H4<2,"Under 2 years","2+ years") -> 2+ years
A5: LN-00004 | B5: Auto Loan | C5: 9200 | D5: 11.18 | E5: 59.8 | F5: 1 | G5: Contract | H5: 22 | I5: 41014 | J5: 611 | K5: {=_xlfn.IFS(J5<600,"520-599",J5<650,"600-649",J5<700,"650-699",J5<750,"700-749",TRUE,"750+")} -> 600-649 | L5: {=_xlfn.IFS(E5<20,"1. Under 20",E5<30,"2. 20-29",E5<40,"3. 30-39",E5<50,"4. 40-49",E5<60,"5. 50-59",E5<70,"6. 60-69",E5<80,"7. 70-79",TRUE,"8. 80+")} -> 5. 50-59 | M5: =IF(H5<2,"Under 2 years","2+ years") -> 2+ years
A6: LN-00005 | B6: Moving | C6: 11200 | D6: 9.66 | E6: 44.1 | F6: 0 | G6: Full-Time | H6: 19 | I6: 35036 | J6: 701 | K6: {=_xlfn.IFS(J6<600,"520-599",J6<650,"600-649",J6<700,"650-699",J6<750,"700-749",TRUE,"750+")} -> 700-749 | L6: {=_xlfn.IFS(E6<20,"1. Under 20",E6<30,"2. 20-29",E6<40,"3. 30-39",E6<50,"4. 40-49",E6<60,"5. 50-59",E6<70,"6. 60-69",E6<80,"7. 70-79",TRUE,"8. 80+")} -> 4. 40-49 | M6: =IF(H6<2,"Under 2 years","2+ years") -> 2+ years
A7: LN-00006 | B7: Education | C7: 28600 | D7: 13.07 | E7: 37.1 | F7: 0 | G7: Full-Time | H7: 18 | I7: 44528 | J7: 715 | K7: {=_xlfn.IFS(J7<600,"520-599",J7<650,"600-649",J7<700,"650-699",J7<750,"700-749",TRUE,"750+")} -> 700-749 | L7: {=_xlfn.IFS(E7<20,"1. Under 20",E7<30,"2. 20-29",E7<40,"3. 30-39",E7<50,"4. 40-49",E7<60,"5. 50-59",E7<70,"6. 60-69",E7<80,"7. 70-79",TRUE,"8. 80+")} -> 3. 30-39 | M7: =IF(H7<2,"Under 2 years","2+ years") -> 2+ years
A8: LN-00007 | B8: Medical Expenses | C8: 39200 | D8: 10.23 | E8: 49.9 | F8: 0 | G8: Contract | H8: 8 | I8: 157047 | J8: 749 | K8: {=_xlfn.IFS(J8<600,"520-599",J8<650,"600-649",J8<700,"650-699",J8<750,"700-749",TRUE,"750+")} -> 700-749 | L8: {=_xlfn.IFS(E8<20,"1. Under 20",E8<30,"2. 20-29",E8<40,"3. 30-39",E8<50,"4. 40-49",E8<60,"5. 50-59",E8<70,"6. 60-69",E8<80,"7. 70-79",TRUE,"8. 80+")} -> 4. 40-49 | M8: =IF(H8<2,"Under 2 years","2+ years") -> 2+ years
A9: LN-00008 | B9: Home Improvement | C9: 36300 | D9: 14.26 | E9: 38.2 | F9: 1 | G9: Self-Employed | H9: 5 | I9: 84210 | J9: 576 | K9: {=_xlfn.IFS(J9<600,"520-599",J9<650,"600-649",J9<700,"650-699",J9<750,"700-749",TRUE,"750+")} -> 520-599 | L9: {=_xlfn.IFS(E9<20,"1. Under 20",E9<30,"2. 20-29",E9<40,"3. 30-39",E9<50,"4. 40-49",E9<60,"5. 50-59",E9<70,"6. 60-69",E9<80,"7. 70-79",TRUE,"8. 80+")} -> 3. 30-39 | M9: =IF(H9<2,"Under 2 years","2+ years") -> 2+ years
A10: LN-00009 | B10: Business Loan | C10: 39000 | D10: 13.73 | E10: 36.8 | F10: 0 | G10: Self-Employed | H10: 5 | I10: 84210 | J10: 576 | K10: {=_xlfn.IFS(J10<600,"520-599",J10<650,"600-649",J10<700,"650-699",J10<750,"700-749",TRUE,"750+")} -> 520-599 | L10: {=_xlfn.IFS(E10<20,"1. Under 20",E10<30,"2. 20-29",E10<40,"3. 30-39",E10<50,"4. 40-49",E10<60,"5. 50-59",E10<70,"6. 60-69",E10<80,"7. 70-79",TRUE,"8. 80+")} -> 3. 30-39 | M10: =IF(H10<2,"Under 2 years","2+ years") -> 2+ years
A11: LN-00010 | B11: Debt Consolidation | C11: 28400 | D11: 11.88 | E11: 67.8 | F11: 1 | G11: Full-Time | H11: 14 | I11: 61289 | J11: 563 | K11: {=_xlfn.IFS(J11<600,"520-599",J11<650,"600-649",J11<700,"650-699",J11<750,"700-749",TRUE,"750+")} -> 520-599 | L11: {=_xlfn.IFS(E11<20,"1. Under 20",E11<30,"2. 20-29",E11<40,"3. 30-39",E11<50,"4. 40-49",E11<60,"5. 50-59",E11<70,"6. 60-69",E11<80,"7. 70-79",TRUE,"8. 80+")} -> 6. 60-69 | M11: =IF(H11<2,"Under 2 years","2+ years") -> 2+ years
A12: LN-00011 | B12: Business Loan | C12: 13300 | D12: 10.91 | E12: 18.6 | F12: 0 | G12: Part-Time | H12: 15 | I12: 63908 | J12: 643 | K12: {=_xlfn.IFS(J12<600,"520-599",J12<650,"600-649",J12<700,"650-699",J12<750,"700-749",TRUE,"750+")} -> 600-649 | L12: {=_xlfn.IFS(E12<20,"1. Under 20",E12<30,"2. 20-29",E12<40,"3. 30-39",E12<50,"4. 40-49",E12<60,"5. 50-59",E12<70,"6. 60-69",E12<80,"7. 70-79",TRUE,"8. 80+")} -> 1. Under 20 | M12: =IF(H12<2,"Under 2 years","2+ years") -> 2+ years
A13: LN-00012 | B13: Business Loan | C13: 2700 | D13: 12.73 | E13: 13.5 | F13: 0 | G13: Part-Time | H13: 15 | I13: 63908 | J13: 643 | K13: {=_xlfn.IFS(J13<600,"520-599",J13<650,"600-649",J13<700,"650-699",J13<750,"700-749",TRUE,"750+")} -> 600-649 | L13: {=_xlfn.IFS(E13<20,"1. Under 20",E13<30,"2. 20-29",E13<40,"3. 30-39",E13<50,"4. 40-49",E13<60,"5. 50-59",E13<70,"6. 60-69",E13<80,"7. 70-79",TRUE,"8. 80+")} -> 1. Under 20 | M13: =IF(H13<2,"Under 2 years","2+ years") -> 2+ years
... A602: LN-00601 | B602: Wedding | C602: 7500 | D602: 10.7 | E602: 62.9 | F602: 0 | G602: Full-Time | H602: 5 | I602: 67070 | J602: 604 | K602: {=_xlfn.IFS(J602<600,"520-599",J602<650,"600-649",J602<700,"650-699",J602<750,"700-749",TRUE,"750+")} -> 600-649 | L602: {=_xlfn.IFS(E602<20,"1. Under 20",E602<30,"2. 20-29",E602<40,"3. 30-39",E602<50,"4. 40-49",E602<60,"5. 50-59",E602<70,"6. 60-69",E602<80,"7. 70-79",TRUE,"8. 80+")} -> 6. 60-69 | M602: =IF(H602<2,"Under 2 years","2+ years") -> 2+ years

Sheet summary
A1: Column1 | B1: Column2
A2: Total_loans | B2: =COUNTA(data!A2:A602) -> 601
A3: Defaults | B3: =SUM(data!F2:F602) -> 146
A4: default rate | B4: =B3/B2 -> 0.24292845
A7: Variable | B7: Correlation with default
A8: credit score | B8: =CORREL(data!J2:J602,data!F2:F602) -> -0.28639377
A9: intrest rate | B9: =CORREL(data!D2:D602,data!F2:F602) -> 0.19893008
A10: dti ratio | B10: =CORREL(data!E2:E602,data!F2:F602) -> 0.19245415
A11: annual income | B11: =CORREL(data!I2:I602,data!F2:F602) -> -0.081545875
A12: loan amount | B12: =CORREL(data!C2:C602,data!F2:F602) -> 0.018116427

Sheet pivot tables 
B4: Credit score | C4: Total loans | D4: Defaults | E4: Default rate
B5: 520-599 | C5: 116 | D5: 57 | E5: 0.49137931
B6: 600-649 | C6: 93 | D6: 27 | E6: 0.29032258
B7: 650-699 | C7: 75 | D7: 21 | E7: 0.28
B8: 700-749 | C8: 86 | D8: 14 | E8: 0.1627907
B9: 750+ | C9: 231 | D9: 27 | E9: 0.11688312
B10: Grand Total | C10: 601 | D10: 146 | E10: 0.24292845
B16: Employment status | C16: Total loans | D16: Defaults | E16: Default rate
B17: Contract | C17: 66 | D17: 15 | E17: 0.22727273
B18: Full-Time | C18: 305 | D18: 73 | E18: 0.23934426
B19: Part-Time | C19: 65 | D19: 18 | E19: 0.27692308
B20: Retired | C20: 60 | D20: 14 | E20: 0.23333333
B21: Self-Employed | C21: 105 | D21: 26 | E21: 0.24761905
B22: Grand Total | C22: 601 | D22: 146 | E22: 0.24292845
B26: Loan purpose | C26: Total loans | D26: Defaultes | E26: Default rate
B27: Auto Loan | C27: 59 | D27: 16 | E27: 0.27118644
B28: Business Loan | C28: 58 | D28: 14 | E28: 0.24137931
B29: Debt Consolidation | C29: 51 | D29: 11 | E29: 0.21568627
B30: Education | C30: 53 | D30: 12 | E30: 0.22641509
B31: Home Improvement | C31: 70 | D31: 20 | E31: 0.28571429
B32: Major Purchase | C32: 68 | D32: 15 | E32: 0.22058824
B33: Medical Expenses | C33: 68 | D33: 14 | E33: 0.20588235
B34: Moving | C34: 56 | D34: 12 | E34: 0.21428571
B35: Vacation | C35: 62 | D35: 14 | E35: 0.22580645
B36: Wedding | C36: 56 | D36: 18 | E36: 0.32142857
B37: Grand Total | C37: 601 | D37: 146 | E37: 0.24292845
B43: Tenure group | C43: Total loans | D43: Defaultes | E43: Default rate
B44: 2+ years | C44: 517 | D44: 117 | E44: 0.22630561
B45: Under 2 years | C45: 84 | D45: 29 | E45: 0.3452381
B46: Grand Total | C46: 601 | D46: 146 | E46: 0.24292845
B53: DTI_bucket | C53: Total loans | D53: Defaultes | E53: Default rate
B54: 1. Under 20 | C54: 48 | D54: 8 | E54: 0.16666667
B55: 2. 20-29 | C55: 78 | D55: 10 | E55: 0.12820513
B56: 3. 30-39 | C56: 107 | D56: 12 | E56: 0.11214953
B57: 4. 40-49 | C57: 97 | D57: 23 | E57: 0.2371134
B58: 5. 50-59 | C58: 99 | D58: 31 | E58: 0.31313131
B59: 6. 60-69 | C59: 76 | D59: 26 | E59: 0.34210526
B60: 7. 70-79 | C60: 44 | D60: 17 | E60: 0.38636364
B61: 8. 80+ | C61: 52 | D61: 19 | E61: 0.36538462
B62: Grand Total | C62: 601 | D62: 146 | E62: 0.24292845
...

Sheet charts
A1: Credit score | B1: Default rate | C1: Target
A2: 520-599 | B2: 0.49137931 | C2: 0.12
A3: 600-649 | B3: 0.29032258 | C3: 0.12
A4: 650-699 | B4: 0.28 | C4: 0.12
A5: 700-749 | B5: 0.1627907 | C5: 0.12
A6: 750+ | B6: 0.11688312 | C6: 0.12
A22: DTI range | B22: Default rate
A23: 1. Under 20 | B23: 0.16666667
A24: 2. 20-29 | B24: 0.12820513
A25: 3. 30-39 | B25: 0.11214953
A26: 4. 40-49 | B26: 0.2371134
A27: 5. 50-59 | B27: 0.31313131
A28: 6. 60-69 | B28: 0.34210526
A29: 7. 70-79 | B29: 0.38636364
A30: 8. 80+ | B30: 0.36538462
A42: Loan purpose | B42: Default rate
A43: Auto Loan | B43: 0.27118644
A44: Business Loan | B44: 0.24137931
A45: Debt Consolidation | B45: 0.21568627
A46: Education | B46: 0.22641509
A47: Home Improvement | B47: 0.28571429
A48: Major Purchase | B48: 0.22058824
A49: Medical Expenses | B49: 0.20588235
A50: Moving | B50: 0.21428571
A51: Vacation | B51: 0.22580645
A52: Wedding | B52: 0.32142857

Sheet Dashboard 
B2: Horizon Financial Group:credit risk analysis dashboard
C4: Total loans | G4: Defaults | K4: Default rate | O4: Company target
C5: =summary!B2 -> 601 | G5: =summary!B3 -> 146 | K5: =summary!B4 -> 0.24292845 | O5: 0.12
